Workbook

Sheet annot_records
A1: 样品ID | B1: 标注类型 | C1: 标注序号 | D1: 峰起点X | E1: 峰起点Y | F1: 峰值点X | G1: 峰值点Y | H1: 峰终点X | I1: 峰终点Y | J1: 重叠峰起点X | K1: 重叠峰起点Y | L1: 重叠峰终点X | M1: 重叠峰终点Y | N1: 重叠峰数量 | O1: 总面积 | P1: 截图文件名 | Q1: 标注日期 | R1: 备注
A2: 1 | B2: 峰标注 | C2: 1 | D2: 211 | E2: 123 | F2: 216 | G2: 1197 | H2: 229 | I2: 246 | P2: sample_1_peak_1_(211-216-229).png | Q2: 20260120 | R2: 峰1：起点(211,123.0) 峰值(216,1197.0) 终点(229,246.0)
A3: 1 | B3: 重叠峰标注 | C3: 1 | J3: 397 | K3: 573 | L3: 433 | M3: 794 | N3: 3 | O3: 31598 | P3: sample_1_overlap_1_(397-433).png | Q3: 20260120 | R3: 重叠峰1：起点(397,573.0) 终点(433,794.0) 总面积=31598.0000 重叠峰数量：3
A4: 1 | B4: 峰标注 | C4: 2 | D4: 526 | E4: 862 | F4: 544 | G4: 1364 | H4: 560 | I4: 947 | P4: sample_1_peak_2_(526-544-560).png | Q4: 20260120 | R4: 峰2：起点(526,862.0) 峰值(544,1364.0) 终点(560,947.0)
A5: 2 | B5: 峰标注 | C5: 1 | D5: 210 | E5: 116 | F5: 215 | G5: 1857 | H5: 228 | I5: 244 | P5: sample_2_peak_1_(210-215-228).png | Q5: 20260120 | R5: 峰1：起点(210,116.0) 峰值(215,1857.0) 终点(228,244.0)
A6: 2 | B6: 重叠峰标注 | C6: 1 | J6: 399 | K6: 515 | L6: 422 | M6: 991 | N6: 2 | O6: 21586 | P6: sample_2_overlap_1_(399-422).png | Q6: 20260120 | R6: 重叠峰1：起点(399,515.0) 终点(422,991.0000000000001) 总面积=21586.0000 重叠峰数量：2
A7: 2 | B7: 峰标注 | C7: 2 | D7: 524 | E7: 974 | F7: 543 | G7: 1902 | H7: 565 | I7: 998 | P7: sample_2_peak_2_(524-543-565).png | Q7: 20260120 | R7: 峰2：起点(524,974.0) 峰值(543,1902.0) 终点(565,998.0)
A8: 3 | B8: 重叠峰标注 | C8: 1 | J8: 202 | K8: 151 | L8: 236 | M8: 387 | N8: 4 | O8: 25567 | P8: sample_3_overlap_1_(202-236).png | Q8: 20260120 | R8: 重叠峰1：起点(202,151.0) 终点(236,387.0) 总面积=25567.0000 重叠峰数量：4
A9: 3 | B9: 重叠峰标注 | C9: 2 | J9: 402 | K9: 541 | L9: 434 | M9: 1094 | N9: 2 | O9: 39468 | P9: sample_3_overlap_2_(402-434).png | Q9: 20260120 | R9: 重叠峰2：起点(402,541.0) 终点(434,1094.0) 总面积=39468.0000 重叠峰数量：2
A10: 3 | B10: 峰标注 | C10: 1 | D10: 525 | E10: 970 | F10: 542 | G10: 1465 | H10: 570 | I10: 951 | P10: sample_3_peak_1_(525-542-560).png | Q10: 20260120 | R10: 峰1：起点(525,970.0000000000001) 峰值(542,1465.0) 终点(560,985.0000000000001)
A11: 4 | B11: 峰标注 | C11: 1 | D11: 210 | E11: 111 | F11: 215 | G11: 1187 | H11: 225 | I11: 248 | P11: sample_4_peak_1_(210-215-225).png | Q11: 20260120 | R11: 峰1：起点(210,111.0) 峰值(215,1187.0) 终点(225,248.0)
A12: 4 | B12: 峰标注 | C12: 2 | D12: 320 | E12: 284 | F12: 323 | G12: 547 | H12: 328 | I12: 297 | P12: sample_4_peak_2_(320-323-328).png | Q12: 20260120 | R12: 峰2：起点(320,284.0) 峰值(323,547.0) 终点(328,297.0)
A13: 4 | B13: 峰标注 | C13: 3 | D13: 525 | E13: 989 | F13: 548 | G13: 2626 | H13: 569 | I13: 936 | P13: sample_4_peak_3_(525-548-569).png | Q13: 20260120 | R13: 峰3：起点(525,989.0) 峰值(548,2626.0) 终点(569,936.0)
A14: 5 | B14: 峰标注 | C14: 1 | D14: 210 | E14: 222 | F14: 214 | G14: 2430 | H14: 224 | I14: 325 | P14: sample_5_peak_1_(210-214-224).png | Q14: 20260120 | R14: 峰1：起点(210,222.0) 峰值(214,2430.0) 终点(224,325.0)
A15: 5 | B15: 峰标注 | C15: 2 | D15: 386 | E15: 692 | F15: 400 | G15: 1309 | H15: 405 | I15: 891 | P15: sample_5_peak_2_(386-400-405).png | Q15: 20260120 | R15: 峰2：起点(386,692.0) 峰值(400,1309.0) 终点(405,890.9999999999999)
A16: 5 | B16: 峰标注 | C16: 3 | D16: 405 | E16: 891 | F16: 415 | G16: 5376 | H16: 424 | I16: 1362 | P16: sample_5_peak_3_(405-415-424).png | Q16: 20260120 | R16: 峰3：起点(405,890.9999999999999) 峰值(415,5376.0) 终点(424,1362.0)
A17: 5 | B17: 峰标注 | C17: 4 | D17: 521 | E17: 1246 | F17: 543 | G17: 3251 | H17: 566 | I17: 1103 | P17: sample_5_peak_4_(521-543-566).png | Q17: 20260120 | R17: 峰4：起点(521,1246.0) 峰值(543,3251.0) 终点(566,1103.0)
A18: 6 | B18: 峰标注 | C18: 1 | D18: 212 | E18: 514 | F18: 214 | G18: 2430 | H18: 224 | I18: 325 | P18: sample_6_peak_1_(212-214-224).png | Q18: 20260120 | R18: 峰1：起点(212,514.0) 峰值(214,2430.0) 终点(224,325.0)
A19: 6 | B19: 峰标注 | C19: 2 | D19: 386 | E19: 692 | F19: 401 | G19: 1170 | H19: 404 | I19: 910 | P19: sample_6_peak_2_(386-401-404).png | Q19: 20260120 | R19: 峰2：起点(386,692.0) 峰值(401,1170.0) 终点(404,910.0)
A20: 6 | B20: 峰标注 | C20: 3 | D20: 407 | E20: 954 | F20: 414 | G20: 6518 | H20: 424 | I20: 1362 | P20: sample_6_peak_3_(407-414-424).png | Q20: 20260120 | R20: 峰3：起点(407,954.0) 峰值(414,6518.0) 终点(424,1362.0)
A21: 6 | B21: 峰标注 | C21: 4 | D21: 521 | E21: 1246 | F21: 544 | G21: 3235 | H21: 564 | I21: 1144 | P21: sample_6_peak_4_(521-544-564).png | Q21: 20260120 | R21: 峰4：起点(521,1246.0) 峰值(544,3235.0) 终点(564,1144.0)
... A31: 16 | B31: 峰标注 | C31: 1 | D31: 266 | E31: 2276 | F31: 283 | G31: 3252 | H31: 299 | I31: 2525 | P31: sample_16_peak_1_(266-283-299).png | Q31: 20260120 | R31: 峰1：起点(266,2276.0) 峰值(283,3252.0) 终点(299,2525.0)
A32: 17 | B32: 重叠峰标注 | C32: 1 | J32: 268 | K32: 2174 | L32: 401 | M32: 2916 | N32: 2 | O32: 408454 | P32: sample_17_overlap_1_(268-401).png | Q32: 20260120 | R32: 重叠峰1：起点(268,2174.0) 终点(401,2916.0) 总面积=408454.0000 重叠峰数量：2
A33: 18 | B33: 重叠峰标注 | C33: 1 | J33: 269 | K33: 1809 | L33: 372 | M33: 2737 | N33: 2 | O33: 268892 | P33: sample_18_overlap_1_(269-372).png | Q33: 20260120 | R33: 重叠峰1：起点(269,1809.0) 终点(372,2737.0) 总面积=268892.0000 重叠峰数量：2
A34: 19 | B34: 重叠峰标注 | C34: 1 | J34: 146 | K34: 2437 | L34: 176 | M34: 3052 | N34: 3 | O34: 98109 | P34: sample_19_overlap_1_(146-176).png | Q34: 20260120 | R34: 重叠峰1：起点(146,2437.0) 终点(176,3052.0) 总面积=98109.0000 重叠峰数量：3
A35: 19 | B35: 重叠峰标注 | C35: 2 | J35: 177 | K35: 3079 | L35: 199 | M35: 2869 | N35: 2 | O35: 86224 | P35: sample_19_overlap_2_(177-199).png | Q35: 20260120 | R35: 重叠峰2：起点(177,3079.0) 终点(199,2869.0) 总面积=86224.0000 重叠峰数量：2
A36: 19 | B36: 重叠峰标注 | C36: 3 | J36: 199 | K36: 2869 | L36: 229 | M36: 2883 | N36: 2 | O36: 100217 | P36: sample_19_overlap_3_(199-229).png | Q36: 20260120 | R36: 重叠峰3：起点(199,2869.0) 终点(229,2883.0) 总面积=100217.0000 重叠峰数量：2
A37: 19 | B37: 峰标注 | C37: 1 | D37: 229 | E37: 2883 | F37: 240 | G37: 5031 | H37: 248 | I37: 2947 | P37: sample_19_peak_1_(229-240-248).png | Q37: 20260120 | R37: 峰1：起点(229,2883.0) 峰值(240,5031.0) 终点(248,2947.0)
A38: 19 | B38: 峰标注 | C38: 2 | D38: 248 | E38: 2947 | F38: 263 | G38: 5100 | H38: 269 | I38: 2793 | P38: sample_19_peak_2_(248-263-269).png | Q38: 20260120 | R38: 峰2：起点(248,2947.0) 峰值(263,5100.0) 终点(269,2793.0)
A39: 19 | B39: 峰标注 | C39: 3 | D39: 352 | E39: 2714 | F39: 371 | G39: 4439 | H39: 382 | I39: 2649 | P39: sample_19_peak_3_(352-371-382).png | Q39: 20260120 | R39: 峰3：起点(352,2714.0) 峰值(371,4439.0) 终点(382,2649.0)
A40: 19 | B40: 重叠峰标注 | C40: 4 | J40: 418 | K40: 2925 | L40: 468 | M40: 3613 | N40: 4 | O40: 356964 | P40: sample_19_overlap_4_(418-468).png | Q40: 20260120 | R40: 重叠峰4：起点(418,2925.0) 终点(468,3613.0) 总面积=356964.0000 重叠峰数量：4
A41: 20 | B41: 重叠峰标注 | C41: 1 | J41: 181 | K41: 2962 | L41: 241 | M41: 2759 | N41: 2 | O41: 306890 | P41: sample_20_overlap_1_(181-241).png | Q41: 20260120 | R41: 重叠峰1：起点(181,2962.0) 终点(241,2759.0) 总面积=306890.0000 重叠峰数量：2
A42: 21 | B42: 峰标注 | C42: 1 | D42: 426 | E42: 3185 | F42: 433 | G42: 22019 | H42: 444 | I42: 4073 | P42: sample_21_peak_1_(426-433-444).png | Q42: 20260120 | R42: 峰1：起点(426,3185.0) 峰值(433,22019.0) 终点(444,4073.0)
A43: 21 | B43: 峰标注 | C43: 2 | D43: 448 | E43: 3878 | F43: 472 | G43: 5071 | H43: 499 | I43: 1292 | P43: sample_21_peak_2_(448-472-499).png | Q43: 20260120 | R43: 峰2：起点(448,3878.0) 峰值(472,5071.0) 终点(499,1292.0)
A44: 22 | B44: 峰标注 | C44: 1 | D44: 194 | E44: 2909 | F44: 210 | G44: 6567 | H44: 219 | I44: 2836 | P44: sample_22_peak_1_(194-210-219).png | Q44: 20260120 | R44: 峰1：起点(194,2909.0) 峰值(210,6567.0) 终点(219,2836.0)
A45: 22 | B45: 峰标注 | C45: 2 | D45: 426 | E45: 3098 | F45: 431 | G45: 22098 | H45: 440 | I45: 4012 | P45: sample_22_peak_2_(426-431-440).png | Q45: 20260120 | R45: 峰2：起点(426,3098.0) 峰值(431,22098.0) 终点(440,4012.0)
A46: 22 | B46: 峰标注 | C46: 3 | D46: 442 | E46: 3756 | F46: 474 | G46: 4907 | H46: 499 | I46: 1264 | P46: sample_22_peak_3_(442-474-499).png | Q46: 20260120 | R46: 峰3：起点(442,3756.0) 峰值(474,4907.0) 终点(499,1264.0)
A47: 23 | B47: 峰标注 | C47: 1 | D47: 194 | E47: 3069 | F47: 208 | G47: 5822 | H47: 216 | I47: 3000 | P47: sample_23_peak_1_(194-208-216).png | Q47: 20260120 | R47: 峰1：起点(194,3069.0) 峰值(208,5822.0) 终点(216,3000.0)
A48: 23 | B48: 峰标注 | C48: 2 | D48: 424 | E48: 3630 | F48: 430 | G48: 23328 | H48: 439 | I48: 4433 | P48: sample_23_peak_2_(424-430-439).png | Q48: 20260120 | R48: 峰2：起点(424,3630.0) 峰值(430,23328.0) 终点(439,4433.0)
A49: 24 | B49: 峰标注 | C49: 1 | D49: 190 | E49: 3139 | F49: 209 | G49: 7139 | H49: 222 | I49: 3143 | P49: sample_24_peak_1_(190-209-222).png | Q49: 20260120 | R49: 峰1：起点(190,3139.0) 峰值(209,7139.0) 终点(222,3143.0)
...

Sheet records_data
A1: sample | B1: type(single=1,overlap=2) | C1: left_edge | D1: right_edge | E1: location | F1: height | G1: area | H1: overlap_num
A2: =annot_records!A2 -> 1 | B2: =IF(annot_records!B2="峰标注",1,2) -> 1 | C2: =IF(B2=1,annot_records!D2,annot_records!J2) -> 211 | D2: =IF(B2=1,annot_records!H2,annot_records!L2) -> 229 | E2: =IF(B2=1,annot_records!F2,-1) -> 216 | F2: =IF(B2=1,annot_records!G2-(annot_records!E2+annot_records!I2)/2,-1) -> 1012.5 | G2: =IF(B2=2,annot_records!O2-(annot_records!M2+annot_records!K2)*(annot_records!L2-annot_records!J2)/2,-1) -> -1 | H2: =IF(B2=2,annot_records!N2,-1) -> -1
A3: =annot_records!A3 -> 1 | B3: =IF(annot_records!B3="峰标注",1,2) -> 2 | C3: =IF(B3=1,annot_records!D3,annot_records!J3) -> 397 | D3: =IF(B3=1,annot_records!H3,annot_records!L3) -> 433 | E3: =IF(B3=1,annot_records!F3,-1) -> -1 | F3: =IF(B3=1,annot_records!G3-(annot_records!E3+annot_records!I3)/2,-1) -> -1 | G3: =IF(B3=2,annot_records!O3-(annot_records!M3+annot_records!K3)*(annot_records!L3-annot_records!J3)/2,-1) -> 6992 | H3: =IF(B3=2,annot_records!N3,-1) -> 3
A4: =annot_records!A4 -> 1 | B4: =IF(annot_records!B4="峰标注",1,2) -> 1 | C4: =IF(B4=1,annot_records!D4,annot_records!J4) -> 526 | D4: =IF(B4=1,annot_records!H4,annot_records!L4) -> 560 | E4: =IF(B4=1,annot_records!F4,-1) -> 544 | F4: =IF(B4=1,annot_records!G4-(annot_records!E4+annot_records!I4)/2,-1) -> 459.5 | G4: =IF(B4=2,annot_records!O4-(annot_records!M4+annot_records!K4)*(annot_records!L4-annot_records!J4)/2,-1) -> -1 | H4: =IF(B4=2,annot_records!N4,-1) -> -1
A5: =annot_records!A5 -> 2 | B5: =IF(annot_records!B5="峰标注",1,2) -> 1 | C5: =IF(B5=1,annot_records!D5,annot_records!J5) -> 210 | D5: =IF(B5=1,annot_records!H5,annot_records!L5) -> 228 | E5: =IF(B5=1,annot_records!F5,-1) -> 215 | F5: =IF(B5=1,annot_records!G5-(annot_records!E5+annot_records!I5)/2,-1) -> 1677 | G5: =IF(B5=2,annot_records!O5-(annot_records!M5+annot_records!K5)*(annot_records!L5-annot_records!J5)/2,-1) -> -1 | H5: =IF(B5=2,annot_records!N5,-1) -> -1
A6: =annot_records!A6 -> 2 | B6: =IF(annot_records!B6="峰标注",1,2) -> 2 | C6: =IF(B6=1,annot_records!D6,annot_records!J6) -> 399 | D6: =IF(B6=1,annot_records!H6,annot_records!L6) -> 422 | E6: =IF(B6=1,annot_records!F6,-1) -> -1 | F6: =IF(B6=1,annot_records!G6-(annot_records!E6+annot_records!I6)/2,-1) -> -1 | G6: =IF(B6=2,annot_records!O6-(annot_records!M6+annot_records!K6)*(annot_records!L6-annot_records!J6)/2,-1) -> 4267 | H6: =IF(B6=2,annot_records!N6,-1) -> 2
A7: =annot_records!A7 -> 2 | B7: =IF(annot_records!B7="峰标注",1,2) -> 1 | C7: =IF(B7=1,annot_records!D7,annot_records!J7) -> 524 | D7: =IF(B7=1,annot_records!H7,annot_records!L7) -> 565 | E7: =IF(B7=1,annot_records!F7,-1) -> 543 | F7: =IF(B7=1,annot_records!G7-(annot_records!E7+annot_records!I7)/2,-1) -> 916 | G7: =IF(B7=2,annot_records!O7-(annot_records!M7+annot_records!K7)*(annot_records!L7-annot_records!J7)/2,-1) -> -1 | H7: =IF(B7=2,annot_records!N7,-1) -> -1
A8: =annot_records!A8 -> 3 | B8: =IF(annot_records!B8="峰标注",1,2) -> 2 | C8: =IF(B8=1,annot_records!D8,annot_records!J8) -> 202 | D8: =IF(B8=1,annot_records!H8,annot_records!L8) -> 236 | E8: =IF(B8=1,annot_records!F8,-1) -> -1 | F8: =IF(B8=1,annot_records!G8-(annot_records!E8+annot_records!I8)/2,-1) -> -1 | G8: =IF(B8=2,annot_records!O8-(annot_records!M8+annot_records!K8)*(annot_records!L8-annot_records!J8)/2,-1) -> 16421 | H8: =IF(B8=2,annot_records!N8,-1) -> 4
A9: =annot_records!A9 -> 3 | B9: =IF(annot_records!B9="峰标注",1,2) -> 2 | C9: =IF(B9=1,annot_records!D9,annot_records!J9) -> 402 | D9: =IF(B9=1,annot_records!H9,annot_records!L9) -> 434 | E9: =IF(B9=1,annot_records!F9,-1) -> -1 | F9: =IF(B9=1,annot_records!G9-(annot_records!E9+annot_records!I9)/2,-1) -> -1 | G9: =IF(B9=2,annot_records!O9-(annot_records!M9+annot_records!K9)*(annot_records!L9-annot_records!J9)/2,-1) -> 13308 | H9: =IF(B9=2,annot_records!N9,-1) -> 2
A10: =annot_records!A10 -> 3 | B10: =IF(annot_records!B10="峰标注",1,2) -> 1 | C10: =IF(B10=1,annot_records!D10,annot_records!J10) -> 525 | D10: =IF(B10=1,annot_records!H10,annot_records!L10) -> 570 | E10: =IF(B10=1,annot_records!F10,-1) -> 542 | F10: =IF(B10=1,annot_records!G10-(annot_records!E10+annot_records!I10)/2,-1) -> 504.5 | G10: =IF(B10=2,annot_records!O10-(annot_records!M10+annot_records!K10)*(annot_records!L10-annot_records!J10)/2,-1) -> -1 | H10: =IF(B10=2,annot_records!N10,-1) -> -1
A11: =annot_records!A11 -> 4 | B11: =IF(annot_records!B11="峰标注",1,2) -> 1 | C11: =IF(B11=1,annot_records!D11,annot_records!J11) -> 210 | D11: =IF(B11=1,annot_records!H11,annot_records!L11) -> 225 | E11: =IF(B11=1,annot_records!F11,-1) -> 215 | F11: =IF(B11=1,annot_records!G11-(annot_records!E11+annot_records!I11)/2,-1) -> 1007.5 | G11: =IF(B11=2,annot_records!O11-(annot_records!M11+annot_records!K11)*(annot_records!L11-annot_records!J11)/2,-1) -> -1 | H11: =IF(B11=2,annot_records!N11,-1) -> -1
A12: =annot_records!A12 -> 4 | B12: =IF(annot_records!B12="峰标注",1,2) -> 1 | C12: =IF(B12=1,annot_records!D12,annot_records!J12) -> 320 | D12: =IF(B12=1,annot_records!H12,annot_records!L12) -> 328 | E12: =IF(B12=1,annot_records!F12,-1) -> 323 | F12: =IF(B12=1,annot_records!G12-(annot_records!E12+annot_records!I12)/2,-1) -> 256.5 | G12: =IF(B12=2,annot_records!O12-(annot_records!M12+annot_records!K12)*(annot_records!L12-annot_records!J12)/2,-1) -> -1 | H12: =IF(B12=2,annot_records!N12,-1) -> -1
A13: =annot_records!A13 -> 4 | B13: =IF(annot_records!B13="峰标注",1,2) -> 1 | C13: =IF(B13=1,annot_records!D13,annot_records!J13) -> 525 | D13: =IF(B13=1,annot_records!H13,annot_records!L13) -> 569 | E13: =IF(B13=1,annot_records!F13,-1) -> 548 | F13: =IF(B13=1,annot_records!G13-(annot_records!E13+annot_records!I13)/2,-1) -> 1663.5 | G13: =IF(B13=2,annot_records!O13-(annot_records!M13+annot_records!K13)*(annot_records!L13-annot_records!J13)/2,-1) -> -1 | H13: =IF(B13=2,annot_records!N13,-1) -> -1
... A279: =annot_records!A279 -> 102 | B279: =IF(annot_records!B279="峰标注",1,2) -> 1 | C279: =IF(B279=1,annot_records!D279,annot_records!J279) -> 406 | D279: =IF(B279=1,annot_records!H279,annot_records!L279) -> 420 | E279: =IF(B279=1,annot_records!F279,-1) -> 416 | F279: =IF(B279=1,annot_records!G279-(annot_records!E279+annot_records!I279)/2,-1) -> 1357 | G279: =IF(B279=2,annot_records!O279-(annot_records!M279+annot_records!K279)*(annot_records!L279-annot_records!J279)/2,-1) -> -1 | H279: =IF(B279=2,annot_records!N279,-1) -> -1
